I'm sorry, but an uncaught exception occurred.

While running game code:
  File "game/script.rpy", line 82, in script call
    call investigator
  File "game/scripts/miscellaneous/investigator.rpy", line 26, in script call
    call scene_0500 from _call_scene_0500
  File "game/scripts/scenes/investigator/scene-0500.rpy", line 45, in script
    $ inventory(3)
  File "game/scripts/scenes/investigator/scene-0500.rpy", line 45, in <module>
    $ inventory(3)
  File "game/script.rpy", line 30, in inventory
    inventario[item]=1
IndexError: list assignment index out of range

-- Full Traceback ------------------------------------------------------------

Full traceback:
  File "game/script.rpy", line 82, in script call
    call investigator
  File "game/scripts/miscellaneous/investigator.rpy", line 26, in script call
    call scene_0500 from _call_scene_0500
  File "game/scripts/scenes/investigator/scene-0500.rpy", line 45, in script
    $ inventory(3)
  File "renpy/ast.py", line 928, in execute
    renpy.python.py_exec_bytecode(self.code.bytecode, self.hide, store=self.store)
  File "renpy/python.py", line 2245, in py_exec_bytecode
    exec(bytecode, globals, locals)
  File "game/scripts/scenes/investigator/scene-0500.rpy", line 45, in <module>
    $ inventory(3)
  File "game/script.rpy", line 30, in inventory
    inventario[item]=1
  File "renpy/python.py", line 875, in do_mutation
    return method(self, *args, **kwargs)
IndexError: list assignment index out of range

Windows-10-10.0.19041
Ren'Py 7.4.11.2266
EMPATHY 0.7
Fri Jun  3 16:40:16 2022
