I'm sorry, but an uncaught exception occurred.

While running game code:
  File "game/script.rpy", line 24, in script call
    call investigator from _call_investigator
  File "game/scripts/miscellaneous/investigator.rpy", line 32, in script call
    call scene_0700
  File "game/scripts/scenes/investigator/scene-0700.rpy", line 39, in script
    leg "Boa tarde senhores"
Exception: Sayer 'leg' is not defined.

-- Full Traceback ------------------------------------------------------------

Full traceback:
  File "game/script.rpy", line 24, in script call
    call investigator from _call_investigator
  File "game/scripts/miscellaneous/investigator.rpy", line 32, in script call
    call scene_0700
  File "game/scripts/scenes/investigator/scene-0700.rpy", line 39, in script
    leg "Boa tarde senhores"
  File "renpy/ast.py", line 681, in execute
    who = eval_who(self.who, self.who_fast)
  File "renpy/ast.py", line 574, in eval_who
    raise Exception("Sayer '%s' is not defined." % who)
Exception: Sayer 'leg' is not defined.

Windows-10-10.0.19041
Ren'Py 7.4.11.2266
EMPATHY 0.1
Sat Apr  9 15:26:33 2022
